# 1. 프로그램 오류

프로그램이 실행 중 어떤 원인에 의해서 오작동을 하거나 비정상적으로 종료되는 경우가 있다. 이러한 결과를 초래하는 원인을 프로그램 에러 또는 오류라고 한다.

- 컴파일 에러 (compile-time error)
	- 컴파일 시에 발생하는 에러
- 런타임 에러 (runtime error)
	- 실행 시에 발생하는 에러
- 논리적 에러 (logical error)
	- 실행은 되지만, 의도와 다르게 동작하는 것

소스코드를 컴파일 하면 컴파일러가 소스코드(\*.java)에 대해 오타나 잘못된 구문, 자료형 체크 등의 기본적인 검사를 수행하여 오류가 있는지를 알려준다. 컴파일을 성공적으로 마치고 나면, 클래스 파일(\*.class)이 생성되고, 생성된 클래스 파일을 실행할 수 있다.

컴파일러가 실행 도중에 발생할 수 있는 잠재적인 오류까지 검사할 수 없기 때문에 컴파일은 잘 되었어도 실행 중에 에러에 의해서 잘못된 결과를 얻거나 프로그램이 비정상적으로 종료될 수 있다.

런타임 에러를 방지하기 위해서는 프로그램의 실행 도중 발생할 수 있는 모든 경우의 수를 고려하여 이에 대한 대비를 하는 것이 필요하다. 자바에서는 실행 시(runtime) 발생할 수 있는 프로그램 오류를 **에러(error)** 와 **예외(exception)** 두 가지로 구분하였다.

- 에러 (error)
	- 프로그램 코드에 의해서 수습될 수 없는 심각한 오류
	- 메모리 부족(OutOfMemoryError), 스택오버플로우(StackOverflowError) 등의 발생하면 복구할 수 없는 심각한 오류
- 예외 (exception)
	- 프로그램 코드에 의해서 수습될 수 있는 다소 미약한 오류

# 2. 예외 클래스의 계층구조

자바에서는 실행 시 발생할 수 있는 오류(Exception과 Error)를 클래스로 정의하였다. 모든 클래스의 조상은 Object클래스이므로 Exception과 Error클래스 역시 Object클래스의 자손들이다.

P.293 그림

예외의 최고 조상은 Exception클래스이다.

- Exception
	- IOException
	- ClassNotFoundException
	- ...
	- RuntimeException
		- ArithmeticException
		- ClassCastException
		- NullPointerException
		- ...
		- IndexOutOfBoundsException

예외 클래스들은 두 그룹으로 나눠질 수 있다.

1. Exception클래스와 그 자손들 (RuntimeException과 자손들 제외)
2. RuntimeException클래스와 그 자손들

## A. Exception과 RuntimeException

RuntimeException클래스와 그 자손 클래스들을 **RuntimeException클래스들**이라 한다.

RuntimeException클래스들을 제외한 나머지 클래스들을 **Exception클래스들**이라 한다.

- Exception클래스들
	- 사용자의 실수와 같은 외적인 요인에 의해 발생하는 예외
		```ad-example

		- 존재하지 않는 파일의 이름을 입력한 경우 (FileNotFoundException)
		- 실수로 클래스의 이름을 잘못 적은 경우 (ClassNotFoundException)
		- 입력한 데이터 형식이 잘못된 경우 (DataFormatException)

		```

- RuntimeException클래스들
	- 프로그래머의 실수로 발생하는 예외
		```ad-example

		- 배열의 범위를 벗어난 경우 (ArrayIndexOutOfBOundsException)
		- 값이 null인 참조변수의 멤버를 호출 (NullPointerException)
		- 클래스간의 형변환을 잘못한 경우 (ClassCastException)
		- 정수를 0으로 나누려는 경우 (ArithmeticException)

		```

# 3. 예외 처리하기 - try - catch문

예외의 처리는 프로그래머가 미리 해주어야 한다.

- 예외처리(exception handling)란, 
	- 정의
		- 프로그램 실행 시 발생할 수 있는 예기치 못한 예외의 발생에 대비한 코드를 작성하는 것이며, 
	- 목적
		- 예외의 발생으로 인한 실행 중인 프로그램의 갑작스런 비정상 종료를 막고, 정상적인 실행상태를 유지할 수 있도록 하는 것이다.

> 에러와 예외는 모두 실행 시(runtime) 발생하는 오류이다.

발생한 예외를 처리하지 못하면, 프로그램은 비정상적으로 종료되며, 처리되지 못한 예외(uncaught exception)는 JVM의 **예외처리기(UncaughtExceptionHandler)** 가 받아서 예외의 원인을 화면에 출력한다.

예외를 처리하기 위해서는 try-catch문을 사용한다.

```java

try{

}catch(Exception1 e1){

}catch(Exception2 e2){

}finally{

}

```

하나의 try블럭 다음에는 여러 종류의 예외를 처리할 수 있도록 하나 이상의 catch블럭이 올 수 있다. 발생한 예외의 종류와 일치하는 최초의 단 한 개의 catch블럭만 수행된다. 발생한 예외의 종류와 일치하는 catch블럭이 없으면 예외는 처리되지 않는다.

> try블럭이나 catch블럭은 괄호 { }를 생략할 수 없다.

## A. try-catch문에서의 흐름

- try블럭 내에서 예외가 발생한 경우
	1. 발생한 예외와 일치하는 catch블럭이 있는지 확인한다.
	2. 일치하는 catch블럭을 찾게 되면, 그 catch블럭 내의 문장들을 수행하고 전체 try-catch문을 빠져나가서 그 다음 문장을 계속해서 수행한다.
	3. 일치하는 catch블럭을 찾지 못하면, 예외는 처리되지 못한다.
- try블럭 내에서 예외가 발생하지 않는 경우
	1. catch블럭을 거치지 않고 전체 try-catch문을 빠져나가서 수행을 계속한다.

```java

class Ex8_1 {
	public static void main(String args[]) {
			System.out.println(1);			
			try {
				System.out.println(2);
				System.out.println(3);
			} catch (Exception e)    {
				System.out.println(4);  // 실행되지 않는다.
			} // try-catch의 끝
			System.out.println(5);
	}
}

```

```java

class Ex8_2 {
	public static void main(String args[]) {
			System.out.println(1);
			try {
				System.out.println(0/0);
				System.out.println(2); 	// 실행되지 않는다.
			} catch (ClassCastException ae)	{
				System.out.println(3);
			}	// try-catch의 끝
			System.out.println(4);
	}	// main메서드의 끝
}

```

## B. 예외의 발생과 catch블럭

catch블럭은 괄호()와 블럭{} 두 부분으로 나눠져 있다. 괄호()내에는 처리하고자 하는 예외와 같은 타입의 참조변수 하나를 선언해야 한다.

예외가 발생하면, 발생한 예외에 해당하는 클래스의 인스턴스가 만들어진다. 예외가 발생한 문장이 try블럭에 포함되어 있다면, 이 예외를 처리할 수 있는 catch블럭이 있는지 찾게 된다.

첫 번째 catch블럭부터 차례로 내려가면서 catch블럭의 괄호()내에 선언된 참조변수의 종류와 생성된 예외클래스의 인스턴스에 instanceof 연산자를 이용해서 검사하게 되는데, 검사결과가 true인 catch블럭을 만날 때까지 검사는 계속된다.

검사결과가 true인 catch블럭을 찾게 되면 블럭에 있는 문장들을 모두 수행한 후에 try-catch문을 빠져나가고 예외는 처리되지만, 검사결과가 true인 catch블럭이 하나도 없으면 예외는 처리되지 않는다.

모든 예외 클래스는 Exception클래스의 자손이므로, catch블럭의 괄호()에 Exception클래스 타입의 참조변수를 선언해 놓으면 어떤 종류의 예외가 발생하더라도 이 catch블럭에 의해서 처리된다.

```java

class Ex8_3 {
	public static void main(String args[]) {
		System.out.println(1);			
		System.out.println(2);

		try {
			System.out.println(3);
			System.out.println(0/0);
			System.out.println(4);  // 실행되지 않는다.
		} catch (Exception e){     // ArithmeticException대신 Exception을 사용.
			System.out.println(5);
		}	// try-catch의 끝

		System.out.println(6);
	}	// main메서드의 끝
}

```


```java

class Ex8_4 {
	public static void main(String args[]) {
		System.out.println(1);			
		System.out.println(2);
		try {
			System.out.println(3);
			System.out.println(0/0);
			System.out.println(4); 	// 실행되지 않는다.
		} catch (ArithmeticException ae)	{
			if (ae instanceof ArithmeticException) 
				System.out.println("true");	
			System.out.println("ArithmeticException");
		} catch (Exception e){
			System.out.println("Exception");
		}	// try-catch의 끝
		System.out.println(6);
	}	// main메서드의 끝
}

```

try-catch문의 마지막에 Exception타입의 참조변수를 선언한 catch블럭을 사용하면, 어떤 종류의 예외가 발생하더라도 이 catch블럭에 의해 처리되도록 할 수 있다.

### a. printStackTrace()와 getMessage()

예외 클래스의 인스턴스에는 발생한 예외에 대한 정보가 담겨있으며, getMessage()와 printStackTrace()를 통해서 이 정보들을 얻을 수 있다.

catch블럭의 괄호()에 선언된 참조변수를 통해 이 인스턴스에 접근할 수 있다. 이 참조변수는 선언된 catch블럭 내에서만 사용 가능하다.

- printStackTrace()
	- 예외발생 당시의 호출스택(Call Stack)에 있었던 메서드의 정보와 예외 메시지를 화면에 출력한다.
- getMessage()
	- 발생한 예외클래스의 인스턴스에 저장된 메시지를 얻을 수 있다.

```java

class Ex8_5 {
	public static void main(String args[]) {
		System.out.println(1);			
		System.out.println(2);

		try {
			System.out.println(3);
			System.out.println(0/0); // 예외발생!!!
			System.out.println(4);   // 실행되지 않는다.
		} catch (ArithmeticException ae)	{
			ae.printStackTrace();
			System.out.println("예외메시지 : " + ae.getMessage());
		}	// try-catch의 끝

		System.out.println(6);
	}	// main메서드의 끝
}

```

예외는 try-catch문에 의해 처리되었으며 프로그램은 정상적으로 종료되었다.

try-catch문으로 예외처리를 하여 예외가 발생해도 비정상적으로 종료하지 않도록 해주는 동시에, printStackTrace() 또는 getMessage()와 같은 메서드를 통해서 예외의 발생 원인을 알 수 있다.

## C. 멀티 catch블럭

- 멀티 catch블럭
	- JDK1.7부터 여러 catch블럭을 **|** 기호를 이용해서, 하나의 catch블럭으로 합칠 수 있게 되었다.

멀티 catch블럭을 이용하여 중복된 코드를 줄일 수 있다. 그리고 **|** 기호로 연결할 수 있는 예외 클래스의 개수에는 제한이 없다.

```java

try{

}catch(ExceptionA | ExceptionB e){
	e.printStackTrace();
}

```

멀티 catch블럭의 **|** 기호로 연결된 예외 클래스가 조상과 자손의 관계에 있다면 컴파일 에러가 발생한다.

```java

try{

}catch(ParentException | ChildException e){ // 에러

}

```

두 예외 클래스가 조상과 자손의 관계에 있다면, 그냥 조상 클래스만 써주는 것과 똑같기 때문이다. 불필요한 코드는 제거하라는 뜻에서 에러가 발생한다.

멀티 catch는 하나의 catch블럭으로 여러 예외를 처리하는 것이기 때문에, 발생한 예외를 멀티 catch블럭으로 처리하게 되었을 때, 멀티 catch블럭 내에서는 실제로 어떤 예외가 발생한 것인지 알 수 없다. 그래서 참조변수 e로 멀티 catch블럭 **|** 기호로 연결된 예외 클래스들의 공통 분모인 조상 예외 클래스에 선언된 멤버만 사용할 수 있다.

```java

try{

}catch(ExceptionA | ExceptionB e){
	e.methodA(); // 에러
	
	if(e instanceof ExceptionA){
		ExceptionA e1 = (ExceptionA)e;
		e1.methodA();
	}
}

```

## D. 예외 발생시키기

키워드 throw를 사용해서 프로그래머가 고의로 예외를 발생시킬 수 있다.

1. 연산자 new를 이용해서 발생시키려는 예외 클래스의 객체를 만든 다음
	- `Exception e = new Exception("고의로 발생");`
2. 키워드 throw를 이용해서 예외를 발생시킨다.
	- `throw e;`

```java

class Ex8_6 {
	public static void main(String args[]) {
		try {
			Exception e = new Exception("고의로 발생시켰음.");
			throw e;	 // 예외를 발생시킴
		//  throw new Exception("고의로 발생시켰음.");

		} catch (Exception e)	{
			System.out.println("에러 메시지 : " + e.getMessage());
			e.printStackTrace();
		}
		System.out.println("프로그램이 정상 종료되었음.");
	}
}

```

Exception인스턴스를 생성할 때, 생성자에 String을 넣어 주면, 이 String이 Exception 인스턴스에 메시지로 저장된다. 이 메시지는 `getMessage()`로 얻을 수 있다.



# 참고문헌

남궁성, "자바의 정석 - 기초편", 도우출판, 2019년

#자바